Workbook

Sheet Read Me
A1: Griffins Medicals - product classification for the online shop
A3: What this is: all 631 ERP products arranged into Parent Type > Shop Category > Shop Sub Category, ready to load into the online shop.
A4: How to use it:
A5: 1. Open the Products sheet. The yellow columns (Parent Type, Shop Category, Shop Sub Category) are my proposal - change any cell using the dropdown.
A6: 2. "Needs Prescription?" is automatic: it says Yes whenever Shop Category = prescription (no tick box needed).
A7: 3. The Notes column shows where I was unsure, or the product has no price, no stock, or is a bundle.
A8: 4. The Shop Menu sheet shows how the shop menu will look, with live counts.
A9: 5. When you are happy, send the file back and I will load it into the ERP database.
A11: How I decided Prescription vs OTC: anything antibiotic, injectable, cardiac, diabetic, cancer, steroid, etc. is Prescription. Only clearly over-the-counter items
A12: (oral paracetamol, cough/cold/allergy, antacids, laxatives, ORS, herbal/homeopathic, mouthwash, saline/decongestant nasal drops, lubricant eye drops, topical pain gels) are OTC.
A13: When unsure I chose Prescription - that is the safer default for a pharmacy. Please review the OTC list (40 products).
A15: Values are lowercase with underscores on purpose - the shop turns them into Title Case in the menu (e.g. pain_and_fever_relief shows as "Pain And Fever Relief").

Sheet Products
A1: SKU | B1: Product Name | C1: Brand | D1: Generic Name | E1: Form | F1: ERP Category | G1: ERP Sub Category | H1: ERP Stock (units) | I1: Pack Size | J1: Online Price (ZMW) | K1: In Stock Online? | L1: Parent Type | M1: Shop Category | N1: Shop Sub Category | O1: Needs Prescription? | P1: Notes / Please Check | Q1: Product ID
A2: PRD-MUXW22EK | B2: Accu-check Glucostick | C2: Roche Diabates Care | D2: Glucostick | F2: Diagnostics & Monitoring(Devices & Supplies) | G2: Blood Glucose Test Strips | H2: 4800 | I2: 50 | J2: 258.89 | K2: Yes | L2: diagnostics | M2: diagnostic_devices | N2: blood_glucose_monitoring | O2: =IF(M2="prescription","Yes","No") -> No | Q2: 75d57c25-89af-4b25-a803-219f4e9e1d20
A3: PRD-MTHV9KLM149 | B3: Codefree Blood Sugar Monitoring Strips | C3: Sd Biosensor, Inc.(Korea) | D3: Glucostick | E3: Medical Device | F3: Diagnostics & Monitoring(Devices & Supplies) | G3: Blood Glucose Test Strips | H3: 2205 | I3: 50 | J3: 258.08 | K3: Yes | L3: diagnostics | M3: diagnostic_devices | N3: blood_glucose_monitoring | O3: =IF(M3="prescription","Yes","No") -> No | Q3: 6973fa0b-d722-4d52-9c29-3bf8726d8751
A4: PRD-1510 | B4: Sinocare Blood Glucose Test Strips | C4: Changsha Sinocare Inc. | D4: Glucostick | E4: Consumable | F4: Diagnostics & Monitoring(Devices & Supplies) | G4: Blood Glucose Test Strips | H4: 14325 | I4: 50 | J4: 216.66 | K4: Yes | L4: diagnostics | M4: diagnostic_devices | N4: blood_glucose_monitoring | O4: =IF(M4="prescription","Yes","No") -> No | Q4: a18968a4-17a0-472e-9805-ef1219c9dbb0
A5: PRD-3326 | B5: Health Nest Blood Pressure Monitor Lt-p30 Arm Type | C5: Health Nest Africa Limited(china/africa) | D5: Bp Machine | F5: Diagnostics & Monitoring(Devices & Supplies) | G5: Blood pressure monitor | H5: 2 | I5: 1 | J5: 420.81 | K5: Yes | L5: diagnostics | M5: diagnostic_devices | N5: blood_pressure_monitors | O5: =IF(M5="prescription","Yes","No") -> No | Q5: 8279ae71-b694-4805-a580-c7222c8d68f3
A6: PRD-E7D66112 | B6: BERLINER HAMMER | C6: Salim Group Of Company | D6: Diagnostic Instrument | E6: Instrument | F6: Diagnostics & Monitoring(Devices & Supplies) | G6: Diagnostic Instruments | H6: 60 | I6: 1 | J6: 291.81 | K6: Yes | L6: diagnostics | M6: diagnostic_devices | N6: diagnostic_instruments | O6: =IF(M6="prescription","Yes","No") -> No | Q6: 2783301f-d4f7-4ce3-a51f-dff24e875e99
A7: PRD-MTHVITBH260 | B7: Diagnostic Set | C7: Salim Group Of Company | D7: Diagnostic Instrument | E7: Instrument | F7: Diagnostics & Monitoring(Devices & Supplies) | G7: Diagnostic Instruments | H7: 40 | I7: 1 | J7: 1190 | K7: Yes | L7: diagnostics | M7: diagnostic_devices | N7: diagnostic_instruments | O7: =IF(M7="prescription","Yes","No") -> No | Q7: e2ba0675-9ce2-4e5b-8d9f-4a8c54d00ba2
A8: PRD-B696D057 | B8: HEAD LIGHT FOR THEATER | C8: Salim Group Of Company | D8: Diagnostic Instrument | E8: Instrument | F8: Diagnostics & Monitoring(Devices & Supplies) | G8: Diagnostic Instruments | H8: 37 | I8: 1 | J8: 247.84 | K8: Yes | L8: diagnostics | M8: diagnostic_devices | N8: diagnostic_instruments | O8: =IF(M8="prescription","Yes","No") -> No | Q8: e72cecb2-22a9-4dc8-a72e-62e69c8deb81
A9: PRD-MTHVIVTQ261 | B9: Laryngoscope With Led Bulb 4 Blade Adult | C9: Salim Group Of Company | D9: Diagnostic Instrument | E9: Instrument | F9: Diagnostics & Monitoring(Devices & Supplies) | G9: Diagnostic Instruments | H9: 49 | I9: 1 | J9: 1610 | K9: Yes | L9: diagnostics | M9: diagnostic_devices | N9: diagnostic_instruments | O9: =IF(M9="prescription","Yes","No") -> No | Q9: 9a5c7ace-212d-459d-b831-cec824b4b31e
A10: PRD-MTHVIYBK262 | B10: Laryngoscope With Led Bulb 4 Blade Paediatric | C10: Salim Group Of Company | D10: Diagnostic Instrument | E10: Instrument | F10: Diagnostics & Monitoring(Devices & Supplies) | G10: Diagnostic Instruments | H10: 10 | I10: 1 | J10: 1610 | K10: Yes | L10: diagnostics | M10: diagnostic_devices | N10: diagnostic_instruments | O10: =IF(M10="prescription","Yes","No") -> No | Q10: a47a63ae-8ba4-4227-89ac-deee31aaf4e4
A11: PRD-MTHVJ0YY263 | B11: Otoscope Set | C11: Salim Group Of Company | D11: Diagnostic Instrument | E11: Instrument | F11: Diagnostics & Monitoring(Devices & Supplies) | G11: Diagnostic Instruments | H11: 36 | I11: 1 | J11: 676.42 | K11: Yes | L11: diagnostics | M11: diagnostic_devices | N11: diagnostic_instruments | O11: =IF(M11="prescription","Yes","No") -> No | Q11: ec9fe5ec-263f-4a3e-a74d-39c568a49325
A12: PRD-083D70E4 | B12: TAYLOR HAMMER | C12: Salim Group Of Company | D12: Diagnostic Instrument | E12: Instrument | F12: Diagnostics & Monitoring(Devices & Supplies) | G12: Diagnostic Instruments | H12: 16 | I12: 1 | J12: 64.04 | K12: Yes | L12: diagnostics | M12: diagnostic_devices | N12: diagnostic_instruments | O12: =IF(M12="prescription","Yes","No") -> No | Q12: d115ffd5-0700-4dfc-a253-ffbdd7a5540b
A13: PRD-MUNYBV7H | B13: Hiv1&2 Test Kit | C13: Oscar Medicare Pvt. Ltd.(india) | D13: Hiv Test Kit | F13: Diagnostics & Monitoring(Devices & Supplies) | G13: Diagnostic Instruments | H13: 0 | I13: 1 | J13: 23.8 | K13: No | L13: diagnostics | M13: diagnostic_devices | N13: test_kits | O13: =IF(M13="prescription","Yes","No") -> No | P13: Out of stock | Q13: fea031e0-5824-4efa-8da4-9ace01c9dc65
A14: PRD-0214 | B14: Ferrous Sulphate 200mg Tablet(leben) | C14: Leben Laboratories Pvt. Ltd.(India) | D14: FERROUS SULPHATE 200MG | E14: Tablet | F14: Vitamins, Minerals & Supplements(Oral Solid) | G14: Vitamins | H14: 58 | I14: 10 | J14: 7.19 | K14: Yes | L14: medicine | M14: health_supplement | N14: blood_booster | O14: =IF(M14="prescription","Yes","No") -> No | Q14: 5a019ca3-0733-4b08-a04e-2e3a47bad215
A15: PRD-7708 | B15: Multitasque Capsule | C15: Scott-Edil Pharmacia Ltd.(India) | D15: GRAPE SEED EXTRACT 50MG+VITAMIN C 40MG+VITAMIN B3 18MG+VITAMIN E10MG+ZINC 10MG+MAGANESIUM 3MG+VITAMIN B5 3MG+VITAMIN B2 1.6MG+VITAMIN B1 1.4MG+VITAMIN B6 1MG+VITAMIN A600MCG+MANGANESE 250MCG+IRON 18MG+BIOTIN 150MCG+FOLIC ACID 100MCG+IODINE 30MCG+COPPER 30MCG+SELENIUM 30MCG+CHROMIUM 25MCG+CITAMIN D3 5MCG+VITAMIN B12 1MCG+MOLYBDENUM 45MCG | E15: Capsule | F15: Vitamins, Minerals & Supplements(Oral Solid) | G15: Vitamins | H15: 300 | I15: 30 | J15: 96.57 | K15: Yes | L15: medicine | M15: health_supplement | N15: blood_booster | O15: =IF(M15="prescription","Yes","No") -> No | Q15: c61ba6ed-d569-4ee8-a2b9-90e308f4c428
A16: PRD-MTHVME5F304 | B16: Roxy Plus 200ml Syrup | C16: Pt Sanbe Farma(Indonesia) | D16: Ferrice Ammonium Citrate 120mg+Folic Acid 0.75mg+Copper Sulphate 0.75mg+Cyanocobalamine 7.5mcg+Manganese Sulphte 0.5mg+Magnesium Chloride 0.5mg/5ml | E16: Syrup | F16: Vitamins, Minerals & Supplements(Oral Liquid) | G16: Iron & Hematinics | H16: 154 | I16: 1 | J16: 51.49 | K16: Yes | L16: medicine | M16: health_supplement | N16: blood_booster | O16: =IF(M16="prescription","Yes","No") -> No | Q16: 31a883d1-2dc1-40bd-8867-58cf771c2b29
A17: PRD-MTHVMPGY308 | B17: Cartilcollagen Sg Capsule | C17: Galaxy Vitacare Pvt. Ltd. | D17: Glucosamine Sulfate 500mg+Cissus Quadrangularis 300mg+Collagen 150mg+Chondroitin Sulphate 100mg+Vitamin C 30mg+Hyaluronic Acid 25mg | E17: Capsule | F17: Vitamins, Minerals & Supplements(Oral Solid) | G17: Joint Health Supplements | H17: 450 | I17: 30 | J17: 344.48 | K17: Yes | L17: medicine | M17: health_supplement | N17: bone_and_joint_health | O17: =IF(M17="prescription","Yes","No") -> No | Q17: 6e2ea113-8bc8-49dc-a4a4-c87abb05ce7c
A18: PRD-MTHV5KSN102 | B18: Uniortho 500mg Tablet | C18: Mankind Pharma Ltd.(India) | D18: Univestin 500mg | E18: Tablet | F18: Vitamins, Minerals & Supplements(Oral Solid) | G18: Joint Health Supplements | H18: 30 | I18: 10 | J18: 161.51 | K18: Yes | L18: medicine | M18: health_supplement | N18: bone_and_joint_health | O18: =IF(M18="prescription","Yes","No") -> No | Q18: 3e82b121-9d81-4ada-b30f-983d13af4fa5
A19: PRD-MTHVMVIU310 | B19: Fertilion F Soft Gelatin Capsule | C19: Galaxy Vitacare Pvt. Ltd. | D19: Inositol(Myo Inositol) 200mg+D-Chiro-Inositol 10mg+Vitamin C 75mg+P.a.b.a 12.5mg+Folic Acid 1.5mg+L-Arginine 10mg+Vitamin B1 5mg+Vitamin B6 5mg+Vitamin B2 2.5mg+Methylcobalamin 500mcg+Retinmol 375mg+Vitamin D3 12.5mcg+Vitamin E 12.5+Magnesium 25mg+Zinc 10mg+Iron 9mg+Copper 750mcg+Manganese 1.5mcg+Selenium 100mcg+Iodine 50mcg+Chromium 50mcg | E19: Capsule | F19: Vitamins, Minerals & Supplements(Oral Solid) | G19: Fertility & Reproductive Support | H19: 330 | I19: 30 | J19: 354.9 | K19: Yes | L19: medicine | M19: health_supplement | N19: fertility_and_reproductive_health | O19: =IF(M19="prescription","Yes","No") -> No | Q19: c240bc56-d642-47bc-a03d-d3b3e3c19b45
A20: PRD-MTHVN568313 | B20: Fertilion M Soft Gelatin Capsule | C20: Galaxy Vitacare Pvt. Ltd. | D20: Lycopene 10mg+Co-Enzyme Q10 50mg+L-Glutathione 50mg+Vitamin E 12.5mg+Vitamin C 75mg+L-Carnitine 50mg+Korean Ginseng Extract 10mg+Zinc 7.5mg+Folic Acid 1.5mg+Iron 5mg+Vitamin B6 5mg+Manganese 2mg+Selenium 100mcg+Vitamin D3 12.5mcg+Vitamin B1 5mg+Methylcobalamine 750mcg+Retinol 375mg | E20: Capsule | F20: Vitamins, Minerals & Supplements(Oral Solid) | G20: Fertility & Reproductive Support | H20: 120 | I20: 30 | J20: 387.36 | K20: Yes | L20: medicine | M20: health_supplement | N20: fertility_and_reproductive_health | O20: =IF(M20="prescription","Yes","No") -> No | Q20: f2c1c243-3e65-437c-8e07-71d01d659833
A21: PRD-MTHV492686 | B21: Weltek Cardio Capsule | C21: Msn Laboratories Private Limited(India) | D21: Coenzyme Q10 100mg+Omega 3 Fatty Acid(Epa 90mg&Dha 60mg)+Lycopene 4mg+Vitamin E 12iu+Selenium 27mcg | E21: Capsule | F21: Vitamins, Minerals & Supplements(Oral Solid) | G21: Cardiac Support Supplements | H21: 300 | I21: 30 | J21: 157.98 | K21: Yes | L21: medicine | M21: health_supplement | N21: heart_health | O21: =IF(M21="prescription","Yes","No") -> No | Q21: 721889c8-7468-4f3f-8256-915d3a3eb8e3
A22: PRD-MUR2DLBK | B22: Nat B Forte Capsule | C22: Mega Lifescience Pty.ltd. | D22: Vitamin B1 100mg+vitamin B6 200mg+vitamin B12 500mcg+folic Acid 200mcg+vitamin E 200iu+vitamin A 5000iu+vitamin D3 0.4mg+copper 1mg+chromium 0.2mg+zinc 15mg | E22: Capsule | F22: Vitamins, Minerals & Supplements(Oral Solid) | G22: Neuro Support Supplements | H22: 150 | I22: 30 | J22: 305.66 | K22: Yes | L22: medicine | M22: health_supplement | N22: mental_focus_and_sleep | O22: =IF(M22="prescription","Yes","No") -> No | Q22: df76ae31-c92e-4890-88c7-b98fe588a22b
A23: PRD-MTHV4TU593 | B23: Weltek Neuro Capsule | C23: Msn Laboratories Private Limited(India) | D23: Methylcobalami 1500mcg+Alpha Lipoic Acid 100mg+Inositol 100mg+Benfotiamine 100mg+Pyridoxine 3mg+Folic Acid 1.5mg | E23: Capsule | F23: Vitamins, Minerals & Supplements(Oral Solid) | G23: Neuro Support Supplements | H23: 60 | I23: 30 | J23: 157.98 | K23: Yes | L23: medicine | M23: health_supplement | N23: mental_focus_and_sleep | O23: =IF(M23="prescription","Yes","No") -> No | Q23: 847c535a-91e9-434d-8f59-9e6966abcd14
A24: PRD-MTHV4QQ092 | B24: Weltek Relaax 30ml | C24: Msn Laboratories Private Limited(India) | D24: L-Tryptophan 5mg+Indian Valerian 30mg+L-Theanine 3mg+Melatonin 3mg/Ml | E24: Syrup | F24: Vitamins, Minerals & Supplements(Oral Liquid) | G24: Sleep & Relaxation Supplements | H24: 10 | I24: 1 | J24: 264.58 | K24: Yes | L24: medicine | M24: health_supplement | N24: mental_focus_and_sleep | O24: =IF(M24="prescription","Yes","No") -> No | Q24: 2378000b-397d-4740-b32c-ad12b7677f04
A25: PRD-MTHV6HE9113 | B25: Foliben 5mg Tablet | C25: Leben Laboratories Pvt. Ltd.(India) | D25: Folic Acid 5mg | E25: Tablet | F25: Vitamins, Minerals & Supplements(Oral Solid) | G25: Vitamins | H25: 2946 | I25: 20 | J25: 7.98 | K25: Yes | L25: medicine | M25: health_supplement | N25: vitamins_and_minerals | O25: =IF(M25="prescription","Yes","No") -> No | Q25: fb871ad2-b939-455c-be76-2165f2a548e6
... A43: PRD-MTHV0XBH48 | B43: Fibolax 5gm*10 Powder Sachet | C43: West-Coast Pharmaceuticals Works Ltd.(India) | D43: Ispaghula Husk 3.5gm/Sachet | E43: Powder For Oral Use | F43: Gastrointestinal(Oral Solid) | G43: Laxatives & Fibre | H43: 11 | I43: 1 | J43: 74.29 | K43: Yes | L43: medicine | M43: otc | N43: digestive_health | O43: =IF(M43="prescription","Yes","No") -> No | Q43: b4f7f630-cf9a-46fa-b48b-9843fcdf4c8b
A44: PRD-MUXWWWGY | B44: Mmt Africure Tablet | C44: Africure Pharmaceuticals(india) Pvt. Ltd. | D44: Magnesium Trisilicate 250MG + Aluminum Hydroxide 120MG | E44: Tablet | F44: Gastrointestinal(Oral Solid) | G44: Proton Pump Inhibitors | H44: 1965 | I44: 10 | J44: 2.4 | K44: Yes | L44: medicine | M44: otc | N44: digestive_health | O44: =IF(M44="prescription","Yes","No") -> No | P44: Antacid (ERP filed under PPIs) | Q44: fe05f9a7-a0a2-4a23-9246-1100a86fcf06
A45: PRD-1684 | B45: Ors 20.5gm | C45: Fdc Limited(India) | D45: Sodium Chloride 2.6gm+Potassium Chloride 1.5gm+Trisodium Citrate Dihydrate 2.9gm+Anhydrous Glucose 13.5gm | E45: Powder For Oral Use | F45: Gastrointestinal(Oral Solid) | G45: Oral Rehydration Salts | H45: 521 | I45: 1 | J45: 5.27 | K45: Yes | L45: medicine | M45: otc | N45: digestive_health | O45: =IF(M45="prescription","Yes","No") -> No | Q45: 5477ff28-0d02-4b76-b531-4ee704120dd2
A46: PRD-MUME2Y57 | B46: Osmolax 3.35gm/5ml 100ml Syrup | C46: Square Pharmaceuticals Plc(Bangladesh) | D46: Lactulose 3.35gm/5ml | E46: Syrup | F46: Gastrointestinal(Oral Liquid) | G46: Laxatives & Fibre | H46: 215 | I46: 1 | J46: 62.17 | K46: Yes | L46: medicine | M46: otc | N46: digestive_health | O46: =IF(M46="prescription","Yes","No") -> No | Q46: 4ead2927-9580-4b6d-a8d5-103b80b41aae
A47: PRD-MTHV4NLU91 | B47: Weltek Fibre 90gm Powder | C47: Msn Laboratories Private Limited(India) | D47: Lactilol Monohydrate 10gm+Ispaghula Husk 3.5gm/15gm | E47: Powder For Oral Use | F47: Gastrointestinal(Oral Solid) | G47: Laxatives & Fibre | H47: 10 | I47: 1 | J47: 264.58 | K47: Yes | L47: medicine | M47: otc | N47: digestive_health | O47: =IF(M47="prescription","Yes","No") -> No | Q47: 3c1b5fc1-e3f1-4502-9bb1-c13a1b2a916f
A48: PRD-7323 | B48: Abnal 0.9% W/v 10ml Nasal Drops | C48: Abacus Parenteral Drugs Ltd. | D48: Sodium Chloride 0.9% W/v | E48: Nasal Spray | F48: Respiratory & ENT(Inhalational) | G48: Nasal Decongestants | H48: 106 | I48: 1 | J48: 16.31 | K48: Yes | L48: medicine | M48: otc | N48: eye_ear_and_nose_care | O48: =IF(M48="prescription","Yes","No") -> No | Q48: ee893347-a9fa-4a20-a3e8-a13a0678d900
A49: PRD-MTHUWXYS8 | B49: Carboxy Ds 0.05% 10ml Eye Drop | C49: Protech Remedies Pvt. Ltd. | D49: Carboxy Methyl Cellulose 0.05% W/V | E49: Eye Drop | F49: Ophthalmology(Topical) | G49: Lubricant Eye Drops | H49: 122 | I49: 1 | J49: 58.7 | K49: Yes | L49: medicine | M49: otc | N49: eye_ear_and_nose_care | O49: =IF(M49="prescription","Yes","No") -> No | Q49: 306bc8b2-6606-48c9-8661-5961a9dae4b4
A50: PRD-MTHV117G49 | B50: Xylone 0.05% W/W 15ml Paediatric Nasal Drops | C50: West-Coast Pharmaceuticals Works Ltd.(India) | D50: Xylometazoline 0.05%W/V | E50: Nasal Spray | F50: Respiratory & ENT(Inhalational) | G50: Nasal Decongestants | H50: 32 | I50: 1 | J50: 163.63 | K50: Yes | L50: medicine | M50: otc | N50: eye_ear_and_nose_care | O50: =IF(M50="prescription","Yes","No") -> No | Q50: c59281d9-613d-45b3-9246-1ed92a23e600
A51: PRD-MTHV149650 | B51: Xylone 0.1% W/W 15ml Adult Nasal Drops | C51: West-Coast Pharmaceuticals Works Ltd.(India) | D51: Xylometazoline 0.01%W/V | E51: Nasal Spray | F51: Respiratory & ENT(Inhalational) | G51: Nasal Decongestants | H51: 21 | I51: 1 | J51: 127.93 | K51: Yes | L51: medicine | M51: otc | N51: eye_ear_and_nose_care | O51: =IF(M51="prescription","Yes","No") -> No | Q51: 505a467d-932a-43ec-88bb-16ac6e1ac10a
A52: PRD-MTHVMYZ8311 | B52: Co-Ex 100ml Syrup | C52: Bhargava Phytolab Pvt. Ltd.(India) | D52: Justicia Adhatoda Q 3.30ml+Passiflora Incarnata Q 3.30ml+Aspidosperma Quebracho Q 1.65ml+Yerba Santa Q 1.65ml+Ipecacuanha Q 1.65ml | E52: Syrup | F52: Homeopathic & Herbal Remedies(Oral Liquid) | G52: Herbal Cough Remedies | H52: 50 | I52: 1 | J52: 70.12 | K52: Yes | L52: medicine | M52: otc | N52: herbal_and_homeopathic | O52: =IF(M52="prescription","Yes","No") -> No | Q52: 820389ed-ef8b-4f0f-87ca-80aaf6fa27f8
A53: PRD-MTHVM3OK301 | B53: Kidflam Tablet | C53: Bhargava Phytolab Pvt. Ltd.(India) | D53: Berberis Vulgaris 75mg+Cantharis Vesicotoiria 75mg+Dioscorea Villosa 25mg+Pteroselinum Sativum 25mg+Stigmata Maydis 40mg+Thuja Occidentalis 20mg+Uva Ursi 20mg+Vesicaria Communis 20mg | E53: Tablet | F53: Homeopathic & Herbal Remedies(Oral Solid) | G53: Urinary Homeopathic | H53: 130 | I53: 15 | J53: 64.42 | K53: Yes | L53: medicine | M53: otc | N53: herbal_and_homeopathic | O53: =IF(M53="prescription","Yes","No") -> No | Q53: b54b060b-97e7-4a70-b6f5-3f7ad2caa728
A54: PRD-MTHVLTIT298 | B54: Meniphib Tablet | C54: Bhargava Phytolab Pvt. Ltd.(India) | D54: Agnus Castus 178mg+Caulophyllum Thalictroids 84mg+Cyclamen Europaeum 84mg+Ignatia Amara 42mg+Iris Versicolor 170mg+Lillium Tigrinum 60mg | E54: Tablet | F54: Homeopathic & Herbal Remedies(Oral Solid) | G54: Women's Health Homeopathic | H54: 420 | I54: 20 | J54: 85.2 | K54: Yes | L54: medicine | M54: otc | N54: herbal_and_homeopathic | O54: =IF(M54="prescription","Yes","No") -> No | Q54: 98f9f06e-197c-49a1-b33a-e71058f8bed2
A55: PRD-MTHVNL6I318 | B55: Prostoral Tablet | C55: Bhargava Phytolab Pvt. Ltd.(India) | D55: Sabal Serrulata 3x+Chimaphila Umbellata 3x+Hydrangea Arborescens 3x+Pareira Brava 6x+Thuja Occidentalis 3x+Staphysagria 3x+Ferrum Picricum 3x | E55: Tablet | F55: Homeopathic & Herbal Remedies(Oral Solid) | G55: Men's Health Herbal | H55: 300 | I55: 30 | J55: 298.13 | K55: Yes | L55: medicine | M55: otc | N55: herbal_and_homeopathic | O55: =IF(M55="prescription","Yes","No") -> No | Q55: 55c6a9d9-4f9c-48ef-9f12-96b48c2b7ebc
A56: PRD-MTHVM6WB302 | B56: Thunder M Tablet | C56: Bhargava Phytolab Pvt. Ltd.(India) | D56: Damiana 0.03ml+Acid Phos 0.13ml+Ginseng 0.02ml+Slenium 0.02mg+Yohimbinum 0.02ml | E56: Tablet | F56: Homeopathic & Herbal Remedies(Oral Solid) | G56: Men's Health Herbal | H56: 360 | I56: 30 | J56: 16.11 | K56: Yes | L56: medicine | M56: otc | N56: herbal_and_homeopathic | O56: =IF(M56="prescription","Yes","No") -> No | Q56: e657186b-0886-41ec-91da-7acff0ea0017
... A61: PRD-MTHUZ28G30 | B61: Curamol 500mg Tablet | C61: Dawa Limited(Kenya) | D61: Paracetamol 500mg | E61: Tablet | F61: Analgesics & Anti-Inflammatory(Oral Solid) | G61: Antipyretics-Analgesics (Paracetamol) | H61: 6 | I61: 10 | J61: 4 | K61: Yes | L61: medicine | M61: otc | N61: pain_and_fever_relief | O61: =IF(M61="prescription","Yes","No") -> No | Q61: ef4d8621-cb93-4665-a274-b7aa325d3450
...

Sheet Lists
A1: Parent Type | B1: Shop Category | C1: Shop Sub Category | E1: Add a new value at the bottom of a list and it becomes selectable on the Products sheet.
A2: medicine | B2: prescription | C2: analgesics_and_anti_inflammatory
A3: cosmetics | B3: otc | C3: antibiotics
A4: surgicals | B4: health_supplement | C4: antifungals
A5: diagnostics | B5: skin_care | C5: antiparasitics_and_antimalarials
B6: surgical_instruments | C6: antivirals
B7: orthopaedic_supports | C7: cardiovascular
B8: consumables_and_hygiene | C8: central_nervous_system
B9: diagnostic_devices | C9: dermatology
C10: diabetes_and_endocrine
C11: metabolic_and_electrolytes
C12: gastrointestinal
C13: urology_and_reproductive_health
C14: hematology
C15: gout_and_musculoskeletal
C16: oncology
C17: immunosuppressants
C18: eye_care
C19: respiratory_and_allergy
C20: vaccines_and_biologicals
C21: contrast_media
... C57: test_kits

Sheet Shop Menu
A1: How the shop menu will look (counts update when you change the Products sheet)
A3: Parent Type (top menu) | B3: Shop Category | C3: Shop Sub Category | D3: Products
A4: medicine | D4: =COUNTIFS(Products!$L$2:$L$632,A4) -> 424
A5: medicine | B5: prescription | D5: =COUNTIFS(Products!$L$2:$L$632,A5,Products!$M$2:$M$632,B5) -> 370
A6: medicine | B6: prescription | C6: analgesics_and_anti_inflammatory | D6: =COUNTIFS(Products!$L$2:$L$632,A6,Products!$M$2:$M$632,B6,Products!$N$2:$N$632,C6) -> 36
A7: medicine | B7: prescription | C7: antibiotics | D7: =COUNTIFS(Products!$L$2:$L$632,A7,Products!$M$2:$M$632,B7,Products!$N$2:$N$632,C7) -> 56
A8: medicine | B8: prescription | C8: antifungals | D8: =COUNTIFS(Products!$L$2:$L$632,A8,Products!$M$2:$M$632,B8,Products!$N$2:$N$632,C8) -> 6
A9: medicine | B9: prescription | C9: antiparasitics_and_antimalarials | D9: =COUNTIFS(Products!$L$2:$L$632,A9,Products!$M$2:$M$632,B9,Products!$N$2:$N$632,C9) -> 14
A10: medicine | B10: prescription | C10: antivirals | D10: =COUNTIFS(Products!$L$2:$L$632,A10,Products!$M$2:$M$632,B10,Products!$N$2:$N$632,C10) -> 5
A11: medicine | B11: prescription | C11: cardiovascular | D11: =COUNTIFS(Products!$L$2:$L$632,A11,Products!$M$2:$M$632,B11,Products!$N$2:$N$632,C11) -> 68
A12: medicine | B12: prescription | C12: central_nervous_system | D12: =COUNTIFS(Products!$L$2:$L$632,A12,Products!$M$2:$M$632,B12,Products!$N$2:$N$632,C12) -> 16
A13: medicine | B13: prescription | C13: dermatology | D13: =COUNTIFS(Products!$L$2:$L$632,A13,Products!$M$2:$M$632,B13,Products!$N$2:$N$632,C13) -> 3
A14: medicine | B14: prescription | C14: diabetes_and_endocrine | D14: =COUNTIFS(Products!$L$2:$L$632,A14,Products!$M$2:$M$632,B14,Products!$N$2:$N$632,C14) -> 32
A15: medicine | B15: prescription | C15: metabolic_and_electrolytes | D15: =COUNTIFS(Products!$L$2:$L$632,A15,Products!$M$2:$M$632,B15,Products!$N$2:$N$632,C15) -> 1
A16: medicine | B16: prescription | C16: gastrointestinal | D16: =COUNTIFS(Products!$L$2:$L$632,A16,Products!$M$2:$M$632,B16,Products!$N$2:$N$632,C16) -> 15
A17: medicine | B17: prescription | C17: urology_and_reproductive_health | D17: =COUNTIFS(Products!$L$2:$L$632,A17,Products!$M$2:$M$632,B17,Products!$N$2:$N$632,C17) -> 14
... A25: medicine | B25: prescription | C25: contrast_media | D25: =COUNTIFS(Products!$L$2:$L$632,A25,Products!$M$2:$M$632,B25,Products!$N$2:$N$632,C25) -> 1
A26: medicine | B26: otc | D26: =COUNTIFS(Products!$L$2:$L$632,A26,Products!$M$2:$M$632,B26) -> 40
A27: medicine | B27: otc | C27: pain_and_fever_relief | D27: =COUNTIFS(Products!$L$2:$L$632,A27,Products!$M$2:$M$632,B27,Products!$N$2:$N$632,C27) -> 9
A28: medicine | B28: otc | C28: cough_cold_and_allergy | D28: =COUNTIFS(Products!$L$2:$L$632,A28,Products!$M$2:$M$632,B28,Products!$N$2:$N$632,C28) -> 12
A29: medicine | B29: otc | C29: digestive_health | D29: =COUNTIFS(Products!$L$2:$L$632,A29,Products!$M$2:$M$632,B29,Products!$N$2:$N$632,C29) -> 8
A30: medicine | B30: otc | C30: oral_care | D30: =COUNTIFS(Products!$L$2:$L$632,A30,Products!$M$2:$M$632,B30,Products!$N$2:$N$632,C30) -> 2
A31: medicine | B31: otc | C31: eye_ear_and_nose_care | D31: =COUNTIFS(Products!$L$2:$L$632,A31,Products!$M$2:$M$632,B31,Products!$N$2:$N$632,C31) -> 4
A32: medicine | B32: otc | C32: herbal_and_homeopathic | D32: =COUNTIFS(Products!$L$2:$L$632,A32,Products!$M$2:$M$632,B32,Products!$N$2:$N$632,C32) -> 5
A33: medicine | B33: health_supplement | D33: =COUNTIFS(Products!$L$2:$L$632,A33,Products!$M$2:$M$632,B33) -> 14
A34: medicine | B34: health_supplement | C34: vitamins_and_minerals | D34: =COUNTIFS(Products!$L$2:$L$632,A34,Products!$M$2:$M$632,B34,Products!$N$2:$N$632,C34) -> 2
A35: medicine | B35: health_supplement | C35: blood_booster | D35: =COUNTIFS(Products!$L$2:$L$632,A35,Products!$M$2:$M$632,B35,Products!$N$2:$N$632,C35) -> 3
A36: medicine | B36: health_supplement | C36: bone_and_joint_health | D36: =COUNTIFS(Products!$L$2:$L$632,A36,Products!$M$2:$M$632,B36,Products!$N$2:$N$632,C36) -> 2
A37: medicine | B37: health_supplement | C37: heart_health | D37: =COUNTIFS(Products!$L$2:$L$632,A37,Products!$M$2:$M$632,B37,Products!$N$2:$N$632,C37) -> 1
A38: medicine | B38: health_supplement | C38: mental_focus_and_sleep | D38: =COUNTIFS(Products!$L$2:$L$632,A38,Products!$M$2:$M$632,B38,Products!$N$2:$N$632,C38) -> 3
A39: medicine | B39: health_supplement | C39: fertility_and_reproductive_health | D39: =COUNTIFS(Products!$L$2:$L$632,A39,Products!$M$2:$M$632,B39,Products!$N$2:$N$632,C39) -> 2
A40: medicine | B40: health_supplement | C40: weight_management | D40: =COUNTIFS(Products!$L$2:$L$632,A40,Products!$M$2:$M$632,B40,Products!$N$2:$N$632,C40) -> 1
A41: cosmetics | D41: =COUNTIFS(Products!$L$2:$L$632,A41) -> 0
A42: cosmetics | B42: skin_care | D42: =COUNTIFS(Products!$L$2:$L$632,A42,Products!$M$2:$M$632,B42) -> 0
A43: cosmetics | B43: skin_care | C43: moisturizer | D43: =COUNTIFS(Products!$L$2:$L$632,A43,Products!$M$2:$M$632,B43,Products!$N$2:$N$632,C43) -> 0
A44: cosmetics | B44: skin_care | C44: face_care | D44: =COUNTIFS(Products!$L$2:$L$632,A44,Products!$M$2:$M$632,B44,Products!$N$2:$N$632,C44) -> 0
A45: cosmetics | B45: skin_care | C45: body_care | D45: =COUNTIFS(Products!$L$2:$L$632,A45,Products!$M$2:$M$632,B45,Products!$N$2:$N$632,C45) -> 0
A46: surgicals | D46: =COUNTIFS(Products!$L$2:$L$632,A46) -> 195
A47: surgicals | B47: surgical_instruments | D47: =COUNTIFS(Products!$L$2:$L$632,A47,Products!$M$2:$M$632,B47) -> 98
A48: surgicals | B48: surgical_instruments | C48: forceps | D48: =COUNTIFS(Products!$L$2:$L$632,A48,Products!$M$2:$M$632,B48,Products!$N$2:$N$632,C48) -> 38
...
